<?xml version="1.0"?>
<robot name="pff">

  <material name="black">
    <color rgba="0 0 0 0.92"/>
  </material>
  <material name="white">
    <color rgba="1 1 1 1"/>
  </material>

  <link name="center_axle">
    <visual>
      <geometry>
        <cylinder length="0.8" radius="0.2"/>
      </geometry>
      <origin rpy="1.57075 0 0" xyz="0 0 0"/>
      <material name="white"/>
    </visual>
    <collision>
      <geometry>
        <cylinder length="0.8" radius="0.2"/>
      </geometry>
    </collision>
    <inertial>
      <mass value="1"/>
      <inertia ixx="0.0633" ixy="0.0" ixz="0.0" iyy="0.02" iyz="0.0" izz="0.0633"/>
    </inertial>
  </link>

  <link name="right_wheel">
    <visual>
      <geometry>
        <cylinder length="0.2" radius="1.0"/>
      </geometry>
      <material name="black"/>
    </visual>
    <collision>
      <geometry>
        <cylinder length="0.2" radius="1.0"/>
      </geometry>
    </collision>
    <inertial>
      <mass value="10"/>
      <inertia ixx="2.533" ixy="0.0" ixz="0.0" iyy="2.533" iyz="0.0" izz="5"/>
    </inertial>
  </link>

  <link name="left_wheel">
    <visual>
      <geometry>
        <cylinder length="0.2" radius="1.0"/>
      </geometry>
      <material name="black"/>
    </visual>
    <collision>
      <geometry>
        <cylinder length="0.2" radius="1.0"/>
      </geometry>
    </collision>
    <inertial>
      <mass value="10"/>
      <inertia ixx="2.533" ixy="0.0" ixz="0.0" iyy="2.533" iyz="0.0" izz="0.02"/>
    </inertial>
  </link>

  <joint name="axle_to_right_wheel" type="continuous">
    <parent link="center_axle"/>
    <child link="right_wheel"/>
    <axis xyz="0 0 1"/>
    <origin rpy="1.57075 0 0" xyz="0 -0.4 0"/>
  </joint>

  <joint name="axle_to_left_wheel" type="continuous">
    <parent link="center_axle"/>
    <child link="left_wheel"/>
    <axis xyz="0 0 1"/>
    <origin rpy="1.57075 0 0" xyz="0 0.4 0"/>
  </joint>

</robot>
